# 에러처리
### 프로그램에서 에러가 발생하면 그 상황에 대한 적절한 처리를 하는 과정

<br/>

#### Swift에서는 **런타임 에러**가 발생한 경우 그것의 처리를 위해 에러의 발생(throwing), 감지(catching), 전파(propagating), 조작(manipulating)을 지원하는 일급 클래스를 제공한다.

<br/>

---

<br/>

## 에러처리의 과정
### (1) 에러 정의
#### 에러가 발생하는 경우를 미리 열거형으로 정의
```swift
enum SomeError: Error {   // Error 프로토콜 채택
    case aError
    case bError
    case cError
}
```

<br/>

### (2) 에러가 발생할 수 있는 함수 정의
```swift
// 타입 형태
// () throws -> ()
// (Int) throws -> (Bool)

// 매개변수와 리턴값 사이에 "throws키워드 추가"
func doSomething(num: Int) throws -> Bool {
    if num < 0 {
        throw SomeError.aError   // "throw"키워드를 사용하여 에러 던지기
    }
    
    return num >= 10 ? true : false
}
```

<br/>

### (3) 에러가 발생할 수 있는 함수의 처리(실행)
#### try와 do-catch문으로 처리
#### 에러발생 가능성이 있는 함수는 try키워드를 앞에 붙여서 사용해야됨
#### Error 프로토콜을 채택한 열거형을 사용하여 분기처리가 가능
```swift
do {       // 정상적인 경우의 처리 상황
    let result: Bool = try doSomething(num: 1)
    print("결과 : \(result)")
    
} catch SomeError.aError {  // 에러가 발생하는 경우 (do블럭을 실행하다가 에러가 발생하면 catch블럭을 실행)
    print("a Error!!")
} catch SomeError.bError {
    print("b Error!!")
} catch SomeError.cError {
    print("c Error!!")
} catch {
    print("Error!!")
}
```

<br/>
<br/>

## <전체코드>
```swift
// 열거형으로 에러 정의
enum SomeError: Error {
    case aError
    case bError
    case cError
}
 

// 에러가 발생할 수 있는 함수 정의
func doSomething(num: Int) throws -> Bool {
    if num < 0 {
        throw SomeError.aError
    }
    
    return num >= 10 ? true : false
}


// 에러가 발생할 수 있는 함수의 실행
do {       // 정상적인 경우의 처리 상황
    let result: Bool = try doSomething(num: 1)
    print("결과 : \(result)")
    
} catch SomeError.aError {  // 에러가 발생하는 경우 (do블럭을 실행하다가 에러가 발생하면 catch블럭을 실행)
    print("a Error!!")
} catch SomeError.bError {
    print("b Error!!")
} catch SomeError.cError {
    print("c Error!!")
} catch {
    print("Error!!")
}
```

<br/>
<br/>

---

<br/>
<br/>

## 에러를 처리하는 방법 - try / try? / try!
### (1) 정식 처리 방법
#### do-catch를 사용하는 정석 방법
```swift
do {
    let result: Bool = try doSomething(num: 7)
    print("결과 : \(result)")
    
} catch {
    print("Error!!")
}
```

<br/>

### (2) Optional try
* 정상적인 경우 ==> (Optional)리턴타입으로 리턴
* 에러가 발생 ==> nil 리턴
```swift
// do-catch문 없이 사용
let result: Bool? = try? doSomething(num: 10)
```


<br/>

### (2) Forced try
* 정상적인 경우 ==> 리턴타입으로 리턴
* 에러가 발생 ==> 런타입에러 발생
```swift
// 반드시 성공하는 경우에만 사용!
let result: Bool = try! doSomething(num: 10)
```

<br/>

### 뇌피셜 : Optional try, Forced try를 왜 굳이 쓸까?
#### **같은 함수**를 사용하더라도..!!
1. 던져지는 에러의 종류에 따라 구체적인 분기처리가 필요하다 👉 정식문법
2. 에러가 발생하는지 여부만 판단하여 처리하면 되는 경우 👉 Optional try
3. 입력되는 매개변수가 불변하는 리터럴값이고, 해당 값을 넣으면 반드시 성공한다 👉 Forced try

<br/>

#### so. => 에러가 발생할 수 있는 같은 함수를 사용하더라도, 사용되는 부분에 따라서 필요한 처리를 간편하게 사용할 수 있는 것 같다. (개발자가 편해지게!)

<br/>
<br/>

---

<br/>
<br/>

## Catch블럭 처리법
#### catch블럭은 do블럭에서 발생한 에러만을 처리하는 블럭
#### 모든 에러의 경우를 처리해야 함 (글로벌 스코프에서는 모든 에러를 처리하지 않아도 컴파일에러 발생하지 않음)

<br/>

### (1) catch 패턴을 사용하는 경우
#### Swift 5.3 ~ : catch 뒤의 케이스를 여러개 나열할 수 있음 (switch문 처럼)
#### ex) catch SomrError.aError, SomrError.bError ...
```swift
do {
    let result: Bool = try doSomething(num: 7)
    print("결과 : \(result)")
    
} catch SomeError.aError {  // where절을 추가해서, 매칭시킬 여러 패턴에 조건을 추가할 수 있음
    print("a Error 발생")
    
} catch {  // default 처리
    print("a를 제외한 다른 에러 발생")
    
}
```

<br/>

### (2) catch 패턴 없이 처리
#### error 상수를 제공 => Error프로토콜 타입
#### 타입캐스팅 후 switch문을 사용하여 분기처리
```swift
do {
    let result: Bool = try doSomething(num: -1)
    print("결과 : \(result)")
    
} catch {  // error 상수를 제공 (모든 에러가 이 상수로 넘어옴)
    
    // Error 프로토콜 타입을 타입캐스팅하여 사용
    if let error = error as? SomeError {
        
        // switch문을 사용하여 분기처리
        switch error {
        case .aError:
            print("a에러")
        case .bError:
            print("b에러")
        case .cError:
            print("c에러")
        }
        
    }
}
```

<br/>
<br/>

---

<br/>
<br/>

## 에러를 던지는 함수를 처리하는 함수
#### = 에러를 처리하는 함수

<br/>

### 에러 열거형,  에러를 던지는 함수 정의
```swift
enum SomeError: Error {
    case aError
}

// (무조건 에러를 던진다고 가정)
func throwingFunc() throws {
    throw SomeError.aError
}
```

<br/>

### (1) 정석 에러의 처리
#### 함수를 호출하는 곳에서 do-catch문 사용
```swift
do {
    try throwingFunc()
} catch {
    print(error)
}
```

<br/>

### (2) 함수 내부에서 do-catch문으로 에러를 처리
#### 에러를 던지는 함수를 실행시키고, 예외처리(에러처리)하는 함수
#### 에러를 던지는 함수에서 발생하는 에러를 catch블럭에서 받아서 알맞은 처리
```swift
func handleError() {
    do {
        try throwingFunc()
    } catch {
        print(error)
    }
}

handleError()
```

<br/>

### (3) 함수 내에서 에러를 직접 처리하지 못하는 경우, 에러를 다시 던질 수 있음
#### 에러를 던지는 함수에서 발생한 에러를 그대로 던지기 때문에 catch블럭 생략 가능
#### catch블럭이 생략되면서 do블럭도 생략 가능해짐
```swift
func handleError1() throws {
   // do{
    try throwingFunc()   // catch블럭이 없어도 에러를 밖으로 던질 수 있음 ⭐️
   // }
}
```

<br/>

### (4) rethrowing 함수로 에러 다시 던지기 (rethrows 키워드)
#### 에러를 던지는 함수를 매개변수로 받는 경우, 내부에서 다시 에러를 던질 때 "rethrows" 키워드를 사용
#### ☝️ 핵심은 rethrows키워드를 어떤 상황에서 사용하는가?
```swift
// 다시 에러를 던지는 함수(방법1)
func someFunction1(callback: () throws -> Void) rethrows {
    try callback()    // 에러를 다시 던짐
    // throw (X)  ==>  (직접 던지지 못함 / 매개변수에서 발생한 에러가 그대로 반환됨)
}

// 다시 에러를 던지는 함수(방법2) - 에러변환
func someFunction2(callback: () throws -> Void) rethrows {
    enum ChangedError: Error {
        case cError
    }
    
    do {
        try callback()
    } catch {   // catch구문에서는 throw (O)
        throw ChangedError.cError    // 에러를 변환해서 다시 던짐
    }
}
```


<br/>
<br/>

---

<br/>
<br/>

## 생성자에 throws 사용
#### 생성자도 함수이기 때문에 에러를 던질 수 있다.
#### 크게 중요하진 않음. 이런거 있다 정도만...
```swift
// 에러 정의
enum NameError: Error {
    case noName
}


// 생성자와 메서드에도 적용 가능
class Course {
    var name: String
    
    init(name: String) throws {
        if name == "" {
            throw NameError.noName
        } else {
            self.name = name
            print("수업을 올바르게 생성")
        }
    }
    
}


// 에러 처리 (생성자에 대한)
do {
    let _ = try Course(name: "스위프트5")
} catch NameError.noName {
    print("이름이 없어 수업이 생성 실패하였습니다.")
}
```

<br/>
<br/>

---

<br/>
<br/>

# LocalizedError 프로토콜을 활용한 에러처리 구문 최적화

### LocalizedError Protocol
```swift
public protocol LocalizedError : Error {

    /// A localized message describing what error occurred.
    var errorDescription: String? { get }

    /// A localized message describing the reason for the failure.
    var failureReason: String? { get }

    /// A localized message describing how one might recover from the failure.
    var recoverySuggestion: String? { get }

    /// A localized message providing "help" text if the user requests help.
    var helpAnchor: String? { get }
}
```

<br/>

### 열거형으로 에러 정의
* 프로토콜에 정의되어 있는 errorDescription 연산 프로퍼티를 활용
* 각 에러에 대한 설명을 문자열로 반환
* 에러를 실제로 처리하는 구문에서는 반환받은 문자열을 사용하여 Alert나 Toast를 띄울 수 있다.
```swift
enum TestError: Error {
    case invalidAuthorization
    case tokenEmail
    case emptyParameters
}

extension TestError: LocalizedError {

    var errorDescription: String? {
        switch self {
        case .invalidAuthorization:
            return "토큰이 만료되었습니다. 다시 로그인 해주세요."
        case .tokenEmail:
            return "이미 가입된 회원입니다. 로그인 해주세요"
        case .emptyParameters:
            return "뭔가가 없습니다."
        }
    }
}
```